Workbook
Name budget: 'Budget Dashboard'!$L1
Name current_date: TODAY()
Name expenses_header_row: ROW(expenses[[#Headers],[Expenses]])
Name expenses_max_row: MAX(ROW(expenses[]))
Name expenses_min_row: MIN(ROW(expenses[]))
Name expenses_total_row: ROW('Budget Planning'!$C$48)
Name income_header_row: ROW(income[[#Headers],[Income]])
Name income_max_row: MAX(ROW(income[]))
Name income_min_row: MIN(ROW(income[]))
Name income_total_row: ROW('Budget Planning'!$C$22)
Name item: 'Budget Dashboard'!$J1
Name savings_header_row: ROW(savings[[#Headers],[Savings]])
Name savings_max_row: MAX(ROW(savings[]))
Name savings_min_row: MIN(ROW(savings[]))
Name savings_rate_calculation_type: Settings!$E$22
Name savings_total_row: ROW('Budget Planning'!$C$60)
Name selected_period: Calculation!$E$20
Name selected_period_display: Calculation!$E$21
Name selected_year: Calculation!$E$19
Name shift_late_income_starting_day: Settings!$E$18
Name shift_late_income_status: Settings!$E$16
Name starting_year: Settings!$E$8
Name tracked: 'Budget Dashboard'!$K1
Name type: 'Budget Dashboard'!$I1
Name budget_range: 'Budget Dashboard'!$Q1
Name budget_rank: 'Budget Dashboard'!$R1
Name comb_rank: 'Budget Dashboard'!$S1
Name comb_rank_norm: 'Budget Dashboard'!$U1
Name comb_rank_norm_run_range: 'Budget Dashboard'!$V1
Name comb_rank_range: 'Budget Dashboard'!$T1
Name comb_rank_unique: 'Budget Dashboard'!$W1
Name header_row_id: 'Budget Dashboard'!$D1
Name is_cat: 'Budget Dashboard'!$F1
Name is_empty: 'Budget Dashboard'!$H1
Name is_header: 'Budget Dashboard'!$E1
Name is_total: 'Budget Dashboard'!$G1
Name out_budget: 'Budget Dashboard'!$AA1
Name out_percentage_completed: 'Budget Dashboard'!$AB1
Name out_tracked: 'Budget Dashboard'!$Z1
Name row_id: 'Budget Dashboard'!$C1
Name sort_max_row: 'Budget Dashboard'!$N1
Name sort_min_row: 'Budget Dashboard'!$M1
Name tracked_range: 'Budget Dashboard'!$O1
Name tracked_rank: 'Budget Dashboard'!$P1
Name cc_budget: Calculation!$K1
Name cc_delta: Calculation!$L1
Name cc_in_focus: Calculation!$G1
Name cc_month_number: Calculation!$F1
Name cc_show_rem_budget: Calculation!$I1
Name cc_show_type: Calculation!$H1
Name cc_tracked: Calculation!$J1
Name cc_type: Calculation!$E1

Sheet Settings
B1: Settings
C6: General
D8: Starting Year: | E8: 2025 | G8: Set the starting year (yyyy) once at the beginning and do not change it again.
C12: Budget Tracking & Dashboard
D14: Late Monthly Income
D16: Shift Late Income: | E16: Inactive | G16: Activate this option to treat late income received on or after a certain day of the month as income for the next month. This is especially recommended in case you receive your monthly paycheck towards the end of the month and prefer to consider this income as the disposable income for the next month.
D18: Starting on day x in month: | E18: 20
D20: KPI Calculation in Dashboard
D22: Savings Rate as % of Income: | E22: % allocated to Savings | G22: Choose how you want the savings rate (SR) to be calculated in the dashboard KPI tiles: 1) Active Option (% allocated to Savings): SR = Savings/Income 2) Passive Option (% not allocated to Expenses): SR = (Income - Expenses) / Income

Sheet Budget Planning
B1: Budget Planning
C5: Define starting year in Settings --> | E5: =starting_year | S5: =E5+1 | AG5: =S5+1 | AU5: =AG5+1 | BI5: =AU5+1 | BW5: =BI5+1 | CK5: =BW5+1 | CY5: =CK5+1 | DM5: =CY5+1 | EA5: =DM5+1
E6: =IF(E7=0, "Jan✓", "Jan") | F6: =IF(F7=0, "Feb✓", "Feb") | G6: =IF(G7=0, "Mar✓", "Mar") | H6: =IF(H7=0, "Apr✓", "Apr") | I6: =IF(I7=0, "May✓", "May") | J6: =IF(J7=0, "Jun✓", "Jun") | K6: =IF(K7=0, "Jul✓", "Jul") | L6: =IF(L7=0, "Aug✓", "Aug") | M6: =IF(M7=0, "Sep✓", "Sep") | N6: =IF(N7=0, "Oct✓", "Oct") | O6: =IF(O7=0, "Nov✓", "Nov") | P6: =IF(P7=0, "Dec✓", "Dec") | Q6: =IF(Q7=0, "Total✓", "Total") | S6: =IF(S7=0, "Jan✓", "Jan") | T6: =IF(T7=0, "Feb✓", "Feb") | U6: =IF(U7=0, "Mar✓", "Mar") | V6: =IF(V7=0, "Apr✓", "Apr") | W6: =IF(W7=0, "May✓", "May") | X6: =IF(X7=0, "Jun✓", "Jun") | Y6: =IF(Y7=0, "Jul✓", "Jul") | Z6: =IF(Z7=0, "Aug✓", "Aug") | AA6: =IF(AA7=0, "Sep✓", "Sep") | AB6: =IF(AB7=0, "Oct✓", "Oct") | AC6: =IF(AC7=0, "Nov✓", "Nov") | AD6: =IF(AD7=0, "Dec✓", "Dec") | AE6: =IF(AE7=0, "Total✓", "Total") | AG6: =IF(AG7=0, "Jan✓", "Jan") | AH6: =IF(AH7=0, "Feb✓", "Feb") | AI6: =IF(AI7=0, "Mar✓", "Mar") | AJ6: =IF(AJ7=0, "Apr✓", "Apr") | AK6: =IF(AK7=0, "May✓", "May") | AL6: =IF(AL7=0, "Jun✓", "Jun") | AM6: =IF(AM7=0, "Jul✓", "Jul") | AN6: =IF(AN7=0, "Aug✓", "Aug") | AO6: =IF(AO7=0, "Sep✓", "Sep") | AP6: =IF(AP7=0, "Oct✓", "Oct") | AQ6: =IF(AQ7=0, "Nov✓", "Nov") | AR6: =IF(AR7=0, "Dec✓", "Dec") | AS6: =IF(AS7=0, "Total✓", "Total") | AU6: =IF(AU7=0, "Jan✓", "Jan") | AV6: =IF(AV7=0, "Feb✓", "Feb") | AW6: =IF(AW7=0, "Mar✓", "Mar") | AX6: =IF(AX7=0, "Apr✓", "Apr") | AY6: =IF(AY7=0, "May✓", "May") | AZ6: =IF(AZ7=0, "Jun✓", "Jun") | BA6: =IF(BA7=0, "Jul✓", "Jul") | BB6: =IF(BB7=0, "Aug✓", "Aug") | BC6: =IF(BC7=0, "Sep✓", "Sep") | BD6: =IF(BD7=0, "Oct✓", "Oct") | BE6: =IF(BE7=0, "Nov✓", "Nov") | BF6: =IF(BF7=0, "Dec✓", "Dec") | BG6: =IF(BG7=0, "Total✓", "Total") | BI6: =IF(BI7=0, "Jan✓", "Jan") | BJ6: =IF(BJ7=0, "Feb✓", "Feb") | BK6: =IF(BK7=0, "Mar✓", "Mar") | BL6: =IF(BL7=0, "Apr✓", "Apr") | BM6: =IF(BM7=0, "May✓", "May") | BN6: =IF(BN7=0, "Jun✓", "Jun") | BO6: =IF(BO7=0, "Jul✓", "Jul") | BP6: =IF(BP7=0, "Aug✓", "Aug") | BQ6: =IF(BQ7=0, "Sep✓", "Sep") | BR6: =IF(BR7=0, "Oct✓", "Oct") | BS6: =IF(BS7=0, "Nov✓", "Nov") | BT6: =IF(BT7=0, "Dec✓", "Dec") | BU6: =IF(BU7=0, "Total✓", "Total") | BW6: =IF(BW7=0, "Jan✓", "Jan") | BX6: =IF(BX7=0, "Feb✓", "Feb") | BY6: =IF(BY7=0, "Mar✓", "Mar") | BZ6: =IF(BZ7=0, "Apr✓", "Apr") | CA6: =IF(CA7=0, "May✓", "May") | CB6: =IF(CB7=0, "Jun✓", "Jun") | CC6: =IF(CC7=0, "Jul✓", "Jul") | CD6: =IF(CD7=0, "Aug✓", "Aug") | CE6: =IF(CE7=0, "Sep✓", "Sep") | CF6: =IF(CF7=0, "Oct✓", "Oct") | CG6: =IF(CG7=0, "Nov✓", "Nov") | CH6: =IF(CH7=0, "Dec✓", "Dec") | CI6: =IF(CI7=0, "Total✓", "Total") | CK6: =IF(CK7=0, "Jan✓", "Jan") | CL6: =IF(CL7=0, "Feb✓", "Feb") | CM6: =IF(CM7=0, "Mar✓", "Mar") | CN6: =IF(CN7=0, "Apr✓", "Apr") | CO6: =IF(CO7=0, "May✓", "May") | CP6: =IF(CP7=0, "Jun✓", "Jun") | CQ6: =IF(CQ7=0, "Jul✓", "Jul") | CR6: =IF(CR7=0, "Aug✓", "Aug") | CS6: =IF(CS7=0, "Sep✓", "Sep") | CT6: =IF(CT7=0, "Oct✓", "Oct") | CU6: =IF(CU7=0, "Nov✓", "Nov") | CV6: =IF(CV7=0, "Dec✓", "Dec") | CW6: =IF(CW7=0, "Total✓", "Total") | CY6: =IF(CY7=0, "Jan✓", "Jan") | CZ6: =IF(CZ7=0, "Feb✓", "Feb") | DA6: =IF(DA7=0, "Mar✓", "Mar") | DB6: =IF(DB7=0, "Apr✓", "Apr") | DC6: =IF(DC7=0, "May✓", "May") | DD6: =IF(DD7=0, "Jun✓", "Jun") | DE6: =IF(DE7=0, "Jul✓", "Jul") | DF6: =IF(DF7=0, "Aug✓", "Aug") | DG6: =IF(DG7=0, "Sep✓", "Sep") | DH6: =IF(DH7=0, "Oct✓", "Oct") | DI6: =IF(DI7=0, "Nov✓", "Nov") | DJ6: =IF(DJ7=0, "Dec✓", "Dec") | DK6: =IF(DK7=0, "Total✓", "Total") | DM6: =IF(DM7=0, "Jan✓", "Jan") | DN6: =IF(DN7=0, "Feb✓", "Feb") | DO6: =IF(DO7=0, "Mar✓", "Mar") | DP6: =IF(DP7=0, "Apr✓", "Apr") | DQ6: =IF(DQ7=0, "May✓", "May") | DR6: =IF(DR7=0, "Jun✓", "Jun") | DS6: =IF(DS7=0, "Jul✓", "Jul") | DT6: =IF(DT7=0, "Aug✓", "Aug") | DU6: =IF(DU7=0, "Sep✓", "Sep") | DV6: =IF(DV7=0, "Oct✓", "Oct") | DW6: =IF(DW7=0, "Nov✓", "Nov") | DX6: =IF(DX7=0, "Dec✓", "Dec") | DY6: =IF(DY7=0, "Total✓", "Total") | EA6: =IF(EA7=0, "Jan✓", "Jan") | EB6: =IF(EB7=0, "Feb✓", "Feb") | EC6: =IF(EC7=0, "Mar✓", "Mar") | ED6: =IF(ED7=0, "Apr✓", "Apr") | EE6: =IF(EE7=0, "May✓", "May") | EF6: =IF(EF7=0, "Jun✓", "Jun") | EG6: =IF(EG7=0, "Jul✓", "Jul") | EH6: =IF(EH7=0, "Aug✓", "Aug") | EI6: =IF(EI7=0, "Sep✓", "Sep") | EJ6: =IF(EJ7=0, "Oct✓", "Oct") | EK6: =IF(EK7=0, "Nov✓", "Nov") | EL6: =IF(EL7=0, "Dec✓", "Dec") | EM6: =IF(EM7=0, "Total✓", "Total")
C7: To be allocated: | E7: =E22-(E48+E60) | F7: =F22-(F48+F60) | G7: =G22-(G48+G60) | H7: =H22-(H48+H60) | I7: =I22-(I48+I60) | J7: =J22-(J48+J60) | K7: =K22-(K48+K60) | L7: =L22-(L48+L60) | ... Q7: =Q22-(Q48+Q60) | S7: =S22-(S48+S60) | T7: =T22-(T48+T60) | U7: =U22-(U48+U60) | V7: =V22-(V48+V60) | W7: =W22-(W48+W60) | X7: =X22-(X48+X60) | Y7: =Y22-(Y48+Y60) | Z7: =Z22-(Z48+Z60) | ... AE7: =AE22-(AE48+AE60) | AG7: =AG22-(AG48+AG60) | AH7: =AH22-(AH48+AH60) | AI7: =AI22-(AI48+AI60) | AJ7: =AJ22-(AJ48+AJ60) | AK7: =AK22-(AK48+AK60) | AL7: =AL22-(AL48+AL60) | AM7: =AM22-(AM48+AM60) | AN7: =AN22-(AN48+AN60) | ... AS7: =AS22-(AS48+AS60) | AU7: =AU22-(AU48+AU60) | AV7: =AV22-(AV48+AV60) | AW7: =AW22-(AW48+AW60) | AX7: =AX22-(AX48+AX60) | AY7: =AY22-(AY48+AY60) | AZ7: =AZ22-(AZ48+AZ60) | BA7: =BA22-(BA48+BA60) | BB7: =BB22-(BB48+BB60) | ... BG7: =BG22-(BG48+BG60) | BI7: =BI22-(BI48+BI60) | BJ7: =BJ22-(BJ48+BJ60) | BK7: =BK22-(BK48+BK60) | BL7: =BL22-(BL48+BL60) | BM7: =BM22-(BM48+BM60) | BN7: =BN22-(BN48+BN60) | BO7: =BO22-(BO48+BO60) | BP7: =BP22-(BP48+BP60) | ... BU7: =BU22-(BU48+BU60) | BW7: =BW22-(BW48+BW60) | BX7: =BX22-(BX48+BX60) | BY7: =BY22-(BY48+BY60) | BZ7: =BZ22-(BZ48+BZ60) | CA7: =CA22-(CA48+CA60) | CB7: =CB22-(CB48+CB60) | CC7: =CC22-(CC48+CC60) | CD7: =CD22-(CD48+CD60) | ... CI7: =CI22-(CI48+CI60) | CK7: =CK22-(CK48+CK60) | CL7: =CL22-(CL48+CL60) | CM7: =CM22-(CM48+CM60) | CN7: =CN22-(CN48+CN60) | CO7: =CO22-(CO48+CO60) | CP7: =CP22-(CP48+CP60) | CQ7: =CQ22-(CQ48+CQ60) | CR7: =CR22-(CR48+CR60) | ... CW7: =CW22-(CW48+CW60) | CY7: =CY22-(CY48+CY60) | CZ7: =CZ22-(CZ48+CZ60) | DA7: =DA22-(DA48+DA60) | DB7: =DB22-(DB48+DB60) | DC7: =DC22-(DC48+DC60) | DD7: =DD22-(DD48+DD60) | DE7: =DE22-(DE48+DE60) | DF7: =DF22-(DF48+DF60) | ... DK7: =DK22-(DK48+DK60) | DM7: =DM22-(DM48+DM60) | DN7: =DN22-(DN48+DN60) | DO7: =DO22-(DO48+DO60) | DP7: =DP22-(DP48+DP60) | DQ7: =DQ22-(DQ48+DQ60) | DR7: =DR22-(DR48+DR60) | DS7: =DS22-(DS48+DS60) | DT7: =DT22-(DT48+DT60) | ... DY7: =DY22-(DY48+DY60) | EA7: =EA22-(EA48+EA60) | EB7: =EB22-(EB48+EB60) | EC7: =EC22-(EC48+EC60) | ED7: =ED22-(ED48+ED60) | EE7: =EE22-(EE48+EE60) | EF7: =EF22-(EF48+EF60) | EG7: =EG22-(EG48+EG60) | EH7: =EH22-(EH48+EH60) | ... EM7: =EM22-(EM48+EM60)
C9: Income | E9: =DATE(E$5,1,1) | F9: =DATE(E$5,2,1) | G9: =DATE(E$5,3,1) | H9: =DATE(E$5,4,1) | I9: =DATE(E$5,5,1) | J9: =DATE(E$5,6,1) | K9: =DATE(E$5,7,1) | L9: =DATE(E$5,8,1) | M9: =DATE(E$5,9,1) | N9: =DATE(E$5,10,1) | O9: =DATE(E$5,11,1) | P9: =DATE(E$5,12,1) | Q9: =E$5 | S9: =DATE(S$5,1,1) | T9: =DATE(S$5,2,1) | U9: =DATE(S$5,3,1) | V9: =DATE(S$5,4,1) | W9: =DATE(S$5,5,1) | X9: =DATE(S$5,6,1) | Y9: =DATE(S$5,7,1) | Z9: =DATE(S$5,8,1) | AA9: =DATE(S$5,9,1) | AB9: =DATE(S$5,10,1) | AC9: =DATE(S$5,11,1) | AD9: =DATE(S$5,12,1) | AE9: =S$5 | AG9: =DATE(AG$5,1,1) | AH9: =DATE(AG$5,2,1) | AI9: =DATE(AG$5,3,1) | AJ9: =DATE(AG$5,4,1) | AK9: =DATE(AG$5,5,1) | AL9: =DATE(AG$5,6,1) | AM9: =DATE(AG$5,7,1) | AN9: =DATE(AG$5,8,1) | AO9: =DATE(AG$5,9,1) | AP9: =DATE(AG$5,10,1) | AQ9: =DATE(AG$5,11,1) | AR9: =DATE(AG$5,12,1) | AS9: =AG$5 | AU9: =DATE(AU$5,1,1) | AV9: =DATE(AU$5,2,1) | AW9: =DATE(AU$5,3,1) | AX9: =DATE(AU$5,4,1) | AY9: =DATE(AU$5,5,1) | AZ9: =DATE(AU$5,6,1) | BA9: =DATE(AU$5,7,1) | BB9: =DATE(AU$5,8,1) | BC9: =DATE(AU$5,9,1) | BD9: =DATE(AU$5,10,1) | BE9: =DATE(AU$5,11,1) | BF9: =DATE(AU$5,12,1) | BG9: =AU$5 | BI9: =DATE(BI$5,1,1) | BJ9: =DATE(BI$5,2,1) | BK9: =DATE(BI$5,3,1) | BL9: =DATE(BI$5,4,1) | BM9: =DATE(BI$5,5,1) | BN9: =DATE(BI$5,6,1) | BO9: =DATE(BI$5,7,1) | BP9: =DATE(BI$5,8,1) | BQ9: =DATE(BI$5,9,1) | BR9: =DATE(BI$5,10,1) | BS9: =DATE(BI$5,11,1) | BT9: =DATE(BI$5,12,1) | BU9: =BI$5 | BW9: =DATE(BW$5,1,1) | BX9: =DATE(BW$5,2,1) | BY9: =DATE(BW$5,3,1) | BZ9: =DATE(BW$5,4,1) | CA9: =DATE(BW$5,5,1) | CB9: =DATE(BW$5,6,1) | CC9: =DATE(BW$5,7,1) | CD9: =DATE(BW$5,8,1) | CE9: =DATE(BW$5,9,1) | CF9: =DATE(BW$5,10,1) | CG9: =DATE(BW$5,11,1) | CH9: =DATE(BW$5,12,1) | CI9: =BW$5 | CK9: =DATE(CK$5,1,1) | CL9: =DATE(CK$5,2,1) | CM9: =DATE(CK$5,3,1) | CN9: =DATE(CK$5,4,1) | CO9: =DATE(CK$5,5,1) | CP9: =DATE(CK$5,6,1) | CQ9: =DATE(CK$5,7,1) | CR9: =DATE(CK$5,8,1) | CS9: =DATE(CK$5,9,1) | CT9: =DATE(CK$5,10,1) | CU9: =DATE(CK$5,11,1) | CV9: =DATE(CK$5,12,1) | CW9: =CK$5 | CY9: =DATE(CY$5,1,1) | CZ9: =DATE(CY$5,2,1) | DA9: =DATE(CY$5,3,1) | DB9: =DATE(CY$5,4,1) | DC9: =DATE(CY$5,5,1) | DD9: =DATE(CY$5,6,1) | DE9: =DATE(CY$5,7,1) | DF9: =DATE(CY$5,8,1) | DG9: =DATE(CY$5,9,1) | DH9: =DATE(CY$5,10,1) | DI9: =DATE(CY$5,11,1) | DJ9: =DATE(CY$5,12,1) | DK9: =CY$5 | DM9: =DATE(DM$5,1,1) | DN9: =DATE(DM$5,2,1) | DO9: =DATE(DM$5,3,1) | DP9: =DATE(DM$5,4,1) | DQ9: =DATE(DM$5,5,1) | DR9: =DATE(DM$5,6,1) | DS9: =DATE(DM$5,7,1) | DT9: =DATE(DM$5,8,1) | DU9: =DATE(DM$5,9,1) | DV9: =DATE(DM$5,10,1) | DW9: =DATE(DM$5,11,1) | DX9: =DATE(DM$5,12,1) | DY9: =DM$5 | EA9: =DATE(EA$5,1,1) | EB9: =DATE(EA$5,2,1) | EC9: =DATE(EA$5,3,1) | ED9: =DATE(EA$5,4,1) | EE9: =DATE(EA$5,5,1) | EF9: =DATE(EA$5,6,1) | EG9: =DATE(EA$5,7,1) | EH9: =DATE(EA$5,8,1) | EI9: =DATE(EA$5,9,1) | EJ9: =DATE(EA$5,10,1) | EK9: =DATE(EA$5,11,1) | EL9: =DATE(EA$5,12,1) | EM9: =EA$5
C10: Employment (Net) | Q10: =SUM(E10:P10) | S10: 5000 | AE10: =SUM(S10:AD10) | AS10: =SUM(AG10:AR10) | BG10: =SUM(AU10:BF10) | BU10: =SUM(BI10:BT10) | CI10: =SUM(BW10:CH10) | CW10: =SUM(CK10:CV10) | DK10: =SUM(CY10:DJ10) | DY10: =SUM(DM10:DX10) | EM10: =SUM(EA10:EL10)
C11: Reimbursements | Q11: =SUM(E11:P11) | AE11: =SUM(S11:AD11)
C12: Bonus | Q12: =SUM(E12:P12) | AE12: =SUM(S12:AD12)
C13: Refunds | Q13: =SUM(E13:P13) | AE13: =SUM(S13:AD13)
C14: Side Hustle (Net) | Q14: =SUM(E14:P14) | AE14: =SUM(S14:AD14) | AS14: =SUM(AG14:AR14) | BG14: =SUM(AU14:BF14) | BU14: =SUM(BI14:BT14) | CI14: =SUM(BW14:CH14) | CW14: =SUM(CK14:CV14) | DK14: =SUM(CY14:DJ14) | DY14: =SUM(DM14:DX14) | EM14: =SUM(EA14:EL14)
C15: Other Income | Q15: =SUM(E15:P15) | AE15: =SUM(S15:AD15) | AS15: =SUM(AG15:AR15) | BG15: =SUM(AU15:BF15) | BU15: =SUM(BI15:BT15) | CI15: =SUM(BW15:CH15) | CW15: =SUM(CK15:CV15) | DK15: =SUM(CY15:DJ15) | DY15: =SUM(DM15:DX15) | EM15: =SUM(EA15:EL15)
C16: Enter Income Categoroy | Q16: =SUM(E16:P16) | AE16: =SUM(S16:AD16) | AS16: =SUM(AG16:AR16) | BG16: =SUM(AU16:BF16) | BU16: =SUM(BI16:BT16) | CI16: =SUM(BW16:CH16) | CW16: =SUM(CK16:CV16) | DK16: =SUM(CY16:DJ16) | DY16: =SUM(DM16:DX16) | EM16: =SUM(EA16:EL16)
C17: Enter Income Categoroy | Q17: =SUM(E17:P17) | AE17: =SUM(S17:AD17) | AS17: =SUM(AG17:AR17) | BG17: =SUM(AU17:BF17) | BU17: =SUM(BI17:BT17) | CI17: =SUM(BW17:CH17) | CW17: =SUM(CK17:CV17) | DK17: =SUM(CY17:DJ17) | DY17: =SUM(DM17:DX17) | EM17: =SUM(EA17:EL17)
C18: Enter Income Categoroy | Q18: =SUM(E18:P18) | AE18: =SUM(S18:AD18) | AS18: =SUM(AG18:AR18) | BG18: =SUM(AU18:BF18) | BU18: =SUM(BI18:BT18) | CI18: =SUM(BW18:CH18) | CW18: =SUM(CK18:CV18) | DK18: =SUM(CY18:DJ18) | DY18: =SUM(DM18:DX18) | EM18: =SUM(EA18:EL18)
C19: Enter Income Categoroy | Q19: =SUM(E19:P19) | AE19: =SUM(S19:AD19) | AS19: =SUM(AG19:AR19) | BG19: =SUM(AU19:BF19) | BU19: =SUM(BI19:BT19) | CI19: =SUM(BW19:CH19) | CW19: =SUM(CK19:CV19) | DK19: =SUM(CY19:DJ19) | DY19: =SUM(DM19:DX19) | EM19: =SUM(EA19:EL19)
C20: Enter Income Categoroy | Q20: =SUM(E20:P20) | AE20: =SUM(S20:AD20) | AS20: =SUM(AG20:AR20) | BG20: =SUM(AU20:BF20) | BU20: =SUM(BI20:BT20) | CI20: =SUM(BW20:CH20) | CW20: =SUM(CK20:CV20) | DK20: =SUM(CY20:DJ20) | DY20: =SUM(DM20:DX20) | EM20: =SUM(EA20:EL20)
C21: Enter Income Categoroy | Q21: =SUM(E21:P21) | AE21: =SUM(S21:AD21) | AS21: =SUM(AG21:AR21) | BG21: =SUM(AU21:BF21) | BU21: =SUM(BI21:BT21) | CI21: =SUM(BW21:CH21) | CW21: =SUM(CK21:CV21) | DK21: =SUM(CY21:DJ21) | DY21: =SUM(DM21:DX21) | EM21: =SUM(EA21:EL21)
C22: Total | E22: {=SUM(INDIRECT(ADDRESS(income_min_row,COLUMN())&":"&ADDRESS(income_max_row,COLUMN())))} | F22: {=SUM(INDIRECT(ADDRESS(income_min_row,COLUMN())&":"&ADDRESS(income_max_row,COLUMN())))} | G22: {=SUM(INDIRECT(ADDRESS(income_min_row,COLUMN())&":"&ADDRESS(income_max_row,COLUMN())))} | H22: {=SUM(INDIRECT(ADDRESS(income_min_row,COLUMN())&":"&ADDRESS(income_max_row,COLUMN())))} | I22: {=SUM(INDIRECT(ADDRESS(income_min_row,COLUMN())&":"&ADDRESS(income_max_row,COLUMN())))} | J22: {=SUM(INDIRECT(ADDRESS(income_min_row,COLUMN())&":"&ADDRESS(income_max_row,COLUMN())))} | K22: {=SUM(INDIRECT(ADDRESS(income_min_row,COLUMN())&":"&ADDRESS(income_max_row,COLUMN())))} | L22: {=SUM(INDIRECT(ADDRESS(income_min_row,COLUMN())&":"&ADDRESS(income_max_row,COLUMN())))} | ... Q22: {=SUM(INDIRECT(ADDRESS(income_min_row,COLUMN())&":"&ADDRESS(income_max_row,COLUMN())))} | S22: {=SUM(INDIRECT(ADDRESS(income_min_row,COLUMN())&":"&ADDRESS(income_max_row,COLUMN())))} | T22: {=SUM(INDIRECT(ADDRESS(income_min_row,COLUMN())&":"&ADDRESS(income_max_row,COLUMN())))} | U22: {=SUM(INDIRECT(ADDRESS(income_min_row,COLUMN())&":"&ADDRESS(income_max_row,COLUMN())))} | V22: {=SUM(INDIRECT(ADDRESS(income_min_row,COLUMN())&":"&ADDRESS(income_max_row,COLUMN())))} | W22: {=SUM(INDIRECT(ADDRESS(income_min_row,COLUMN())&":"&ADDRESS(income_max_row,COLUMN())))} | X22: {=SUM(INDIRECT(ADDRESS(income_min_row,COLUMN())&":"&ADDRESS(income_max_row,COLUMN())))} | Y22: {=SUM(INDIRECT(ADDRESS(income_min_row,COLUMN())&":"&ADDRESS(income_max_row,COLUMN())))} | Z22: {=SUM(INDIRECT(ADDRESS(income_min_row,COLUMN())&":"&ADDRESS(income_max_row,COLUMN())))} | ... AE22: {=SUM(INDIRECT(ADDRESS(income_min_row,COLUMN())&":"&ADDRESS(income_max_row,COLUMN())))} | AG22: {=SUM(INDIRECT(ADDRESS(income_min_row,COLUMN())&":"&ADDRESS(income_max_row,COLUMN())))} | AH22: {=SUM(INDIRECT(ADDRESS(income_min_row,COLUMN())&":"&ADDRESS(income_max_row,COLUMN())))} | AI22: {=SUM(INDIRECT(ADDRESS(income_min_row,COLUMN())&":"&ADDRESS(income_max_row,COLUMN())))} | AJ22: {=SUM(INDIRECT(ADDRESS(income_min_row,COLUMN())&":"&ADDRESS(income_max_row,COLUMN())))} | AK22: {=SUM(INDIRECT(ADDRESS(income_min_row,COLUMN())&":"&ADDRESS(income_max_row,COLUMN())))} | AL22: {=SUM(INDIRECT(ADDRESS(income_min_row,COLUMN())&":"&ADDRESS(income_max_row,COLUMN())))} | AM22: {=SUM(INDIRECT(ADDRESS(income_min_row,COLUMN())&":"&ADDRESS(income_max_row,COLUMN())))} | AN22: {=SUM(INDIRECT(ADDRESS(income_min_row,COLUMN())&":"&ADDRESS(income_max_row,COLUMN())))} | ... AS22: {=SUM(INDIRECT(ADDRESS(income_min_row,COLUMN())&":"&ADDRESS(income_max_row,COLUMN())))} | AU22: {=SUM(INDIRECT(ADDRESS(income_min_row,COLUMN())&":"&ADDRESS(income_max_row,COLUMN())))} | AV22: {=SUM(INDIRECT(ADDRESS(income_min_row,COLUMN())&":"&ADDRESS(income_max_row,COLUMN())))} | AW22: {=SUM(INDIRECT(ADDRESS(income_min_row,COLUMN())&":"&ADDRESS(income_max_row,COLUMN())))} | AX22: {=SUM(INDIRECT(ADDRESS(income_min_row,COLUMN())&":"&ADDRESS(income_max_row,COLUMN())))} | AY22: {=SUM(INDIRECT(ADDRESS(income_min_row,COLUMN())&":"&ADDRESS(income_max_row,COLUMN())))} | AZ22: {=SUM(INDIRECT(ADDRESS(income_min_row,COLUMN())&":"&ADDRESS(income_max_row,COLUMN())))} | BA22: {=SUM(INDIRECT(ADDRESS(income_min_row,COLUMN())&":"&ADDRESS(income_max_row,COLUMN())))} | BB22: {=SUM(INDIRECT(ADDRESS(income_min_row,COLUMN())&":"&ADDRESS(income_max_row,COLUMN())))} | ... BG22: {=SUM(INDIRECT(ADDRESS(income_min_row,COLUMN())&":"&ADDRESS(income_max_row,COLUMN())))} | BI22: {=SUM(INDIRECT(ADDRESS(income_min_row,COLUMN())&":"&ADDRESS(income_max_row,COLUMN())))} | BJ22: {=SUM(INDIRECT(ADDRESS(income_min_row,COLUMN())&":"&ADDRESS(income_max_row,COLUMN())))} | BK22: {=SUM(INDIRECT(ADDRESS(income_min_row,COLUMN())&":"&ADDRESS(income_max_row,COLUMN())))} | BL22: {=SUM(INDIRECT(ADDRESS(income_min_row,COLUMN())&":"&ADDRESS(income_max_row,COLUMN())))} | BM22: {=SUM(INDIRECT(ADDRESS(income_min_row,COLUMN())&":"&ADDRESS(income_max_row,COLUMN())))} | BN22: {=SUM(INDIRECT(ADDRESS(income_min_row,COLUMN())&":"&ADDRESS(income_max_row,COLUMN())))} | BO22: {=SUM(INDIRECT(ADDRESS(income_min_row,COLUMN())&":"&ADDRESS(income_max_row,COLUMN())))} | BP22: {=SUM(INDIRECT(ADDRESS(income_min_row,COLUMN())&":"&ADDRESS(income_max_row,COLUMN())))} | ... BU22: {=SUM(INDIRECT(ADDRESS(income_min_row,COLUMN())&":"&ADDRESS(income_max_row,COLUMN())))} | BW22: {=SUM(INDIRECT(ADDRESS(income_min_row,COLUMN())&":"&ADDRESS(income_max_row,COLUMN())))} | BX22: {=SUM(INDIRECT(ADDRESS(income_min_row,COLUMN())&":"&ADDRESS(income_max_row,COLUMN())))} | BY22: {=SUM(INDIRECT(ADDRESS(income_min_row,COLUMN())&":"&ADDRESS(income_max_row,COLUMN())))} | BZ22: {=SUM(INDIRECT(ADDRESS(income_min_row,COLUMN())&":"&ADDRESS(income_max_row,COLUMN())))} | CA22: {=SUM(INDIRECT(ADDRESS(income_min_row,COLUMN())&":"&ADDRESS(income_max_row,COLUMN())))} | CB22: {=SUM(INDIRECT(ADDRESS(income_min_row,COLUMN())&":"&ADDRESS(income_max_row,COLUMN())))} | CC22: {=SUM(INDIRECT(ADDRESS(income_min_row,COLUMN())&":"&ADDRESS(income_max_row,COLUMN())))} | CD22: {=SUM(INDIRECT(ADDRESS(income_min_row,COLUMN())&":"&ADDRESS(income_max_row,COLUMN())))} | ... CI22: {=SUM(INDIRECT(ADDRESS(income_min_row,COLUMN())&":"&ADDRESS(income_max_row,COLUMN())))} | CK22: {=SUM(INDIRECT(ADDRESS(income_min_row,COLUMN())&":"&ADDRESS(income_max_row,COLUMN())))} | CL22: {=SUM(INDIRECT(ADDRESS(income_min_row,COLUMN())&":"&ADDRESS(income_max_row,COLUMN())))} | CM22: {=SUM(INDIRECT(ADDRESS(income_min_row,COLUMN())&":"&ADDRESS(income_max_row,COLUMN())))} | CN22: {=SUM(INDIRECT(ADDRESS(income_min_row,COLUMN())&":"&ADDRESS(income_max_row,COLUMN())))} | CO22: {=SUM(INDIRECT(ADDRESS(income_min_row,COLUMN())&":"&ADDRESS(income_max_row,COLUMN())))} | CP22: {=SUM(INDIRECT(ADDRESS(income_min_row,COLUMN())&":"&ADDRESS(income_max_row,COLUMN())))} | CQ22: {=SUM(INDIRECT(ADDRESS(income_min_row,COLUMN())&":"&ADDRESS(income_max_row,COLUMN())))} | CR22: {=SUM(INDIRECT(ADDRESS(income_min_row,COLUMN())&":"&ADDRESS(income_max_row,COLUMN())))} | ... CW22: {=SUM(INDIRECT(ADDRESS(income_min_row,COLUMN())&":"&ADDRESS(income_max_row,COLUMN())))} | CY22: {=SUM(INDIRECT(ADDRESS(income_min_row,COLUMN())&":"&ADDRESS(income_max_row,COLUMN())))} | CZ22: {=SUM(INDIRECT(ADDRESS(income_min_row,COLUMN())&":"&ADDRESS(income_max_row,COLUMN())))} | DA22: {=SUM(INDIRECT(ADDRESS(income_min_row,COLUMN())&":"&ADDRESS(income_max_row,COLUMN())))} | DB22: {=SUM(INDIRECT(ADDRESS(income_min_row,COLUMN())&":"&ADDRESS(income_max_row,COLUMN())))} | DC22: {=SUM(INDIRECT(ADDRESS(income_min_row,COLUMN())&":"&ADDRESS(income_max_row,COLUMN())))} | DD22: {=SUM(INDIRECT(ADDRESS(income_min_row,COLUMN())&":"&ADDRESS(income_max_row,COLUMN())))} | DE22: {=SUM(INDIRECT(ADDRESS(income_min_row,COLUMN())&":"&ADDRESS(income_max_row,COLUMN())))} | DF22: {=SUM(INDIRECT(ADDRESS(income_min_row,COLUMN())&":"&ADDRESS(income_max_row,COLUMN())))} | ... DK22: {=SUM(INDIRECT(ADDRESS(income_min_row,COLUMN())&":"&ADDRESS(income_max_row,COLUMN())))} | DM22: {=SUM(INDIRECT(ADDRESS(income_min_row,COLUMN())&":"&ADDRESS(income_max_row,COLUMN())))} | DN22: {=SUM(INDIRECT(ADDRESS(income_min_row,COLUMN())&":"&ADDRESS(income_max_row,COLUMN())))} | DO22: {=SUM(INDIRECT(ADDRESS(income_min_row,COLUMN())&":"&ADDRESS(income_max_row,COLUMN())))} | DP22: {=SUM(INDIRECT(ADDRESS(income_min_row,COLUMN())&":"&ADDRESS(income_max_row,COLUMN())))} | DQ22: {=SUM(INDIRECT(ADDRESS(income_min_row,COLUMN())&":"&ADDRESS(income_max_row,COLUMN())))} | DR22: {=SUM(INDIRECT(ADDRESS(income_min_row,COLUMN())&":"&ADDRESS(income_max_row,COLUMN())))} | DS22: {=SUM(INDIRECT(ADDRESS(income_min_row,COLUMN())&":"&ADDRESS(income_max_row,COLUMN())))} | DT22: {=SUM(INDIRECT(ADDRESS(income_min_row,COLUMN())&":"&ADDRESS(income_max_row,COLUMN())))} | ... DY22: {=SUM(INDIRECT(ADDRESS(income_min_row,COLUMN())&":"&ADDRESS(income_max_row,COLUMN())))} | EA22: {=SUM(INDIRECT(ADDRESS(income_min_row,COLUMN())&":"&ADDRESS(income_max_row,COLUMN())))} | EB22: {=SUM(INDIRECT(ADDRESS(income_min_row,COLUMN())&":"&ADDRESS(income_max_row,COLUMN())))} | EC22: {=SUM(INDIRECT(ADDRESS(income_min_row,COLUMN())&":"&ADDRESS(income_max_row,COLUMN())))} | ED22: {=SUM(INDIRECT(ADDRESS(income_min_row,COLUMN())&":"&ADDRESS(income_max_row,COLUMN())))} | EE22: {=SUM(INDIRECT(ADDRESS(income_min_row,COLUMN())&":"&ADDRESS(income_max_row,COLUMN())))} | EF22: {=SUM(INDIRECT(ADDRESS(income_min_row,COLUMN())&":"&ADDRESS(income_max_row,COLUMN())))} | EG22: {=SUM(INDIRECT(ADDRESS(income_min_row,COLUMN())&":"&ADDRESS(income_max_row,COLUMN())))} | EH22: {=SUM(INDIRECT(ADDRESS(income_min_row,COLUMN())&":"&ADDRESS(income_max_row,COLUMN())))} | ... EM22: {=SUM(INDIRECT(ADDRESS(income_min_row,COLUMN())&":"&ADDRESS(income_max_row,COLUMN())))}
C24: Expenses | E24: =DATE(E$5,1,1) | F24: =DATE(E$5,2,1) | G24: =DATE(E$5,3,1) | H24: =DATE(E$5,4,1) | I24: =DATE(E$5,5,1) | J24: =DATE(E$5,6,1) | K24: =DATE(E$5,7,1) | L24: =DATE(E$5,8,1) | M24: =DATE(E$5,9,1) | N24: =DATE(E$5,10,1) | O24: =DATE(E$5,11,1) | P24: =DATE(E$5,12,1) | Q24: =E$5 | S24: =DATE(S$5,1,1) | T24: =DATE(S$5,2,1) | U24: =DATE(S$5,3,1) | V24: =DATE(S$5,4,1) | W24: =DATE(S$5,5,1) | X24: =DATE(S$5,6,1) | Y24: =DATE(S$5,7,1) | Z24: =DATE(S$5,8,1) | AA24: =DATE(S$5,9,1) | AB24: =DATE(S$5,10,1) | AC24: =DATE(S$5,11,1) | AD24: =DATE(S$5,12,1) | AE24: =S$5 | AG24: =DATE(AG$5,1,1) | AH24: =DATE(AG$5,2,1) | AI24: =DATE(AG$5,3,1) | AJ24: =DATE(AG$5,4,1) | AK24: =DATE(AG$5,5,1) | AL24: =DATE(AG$5,6,1) | AM24: =DATE(AG$5,7,1) | AN24: =DATE(AG$5,8,1) | AO24: =DATE(AG$5,9,1) | AP24: =DATE(AG$5,10,1) | AQ24: =DATE(AG$5,11,1) | AR24: =DATE(AG$5,12,1) | AS24: =AG$5 | AU24: =DATE(AU$5,1,1) | AV24: =DATE(AU$5,2,1) | AW24: =DATE(AU$5,3,1) | AX24: =DATE(AU$5,4,1) | AY24: =DATE(AU$5,5,1) | AZ24: =DATE(AU$5,6,1) | BA24: =DATE(AU$5,7,1) | BB24: =DATE(AU$5,8,1) | BC24: =DATE(AU$5,9,1) | BD24: =DATE(AU$5,10,1) | BE24: =DATE(AU$5,11,1) | BF24: =DATE(AU$5,12,1) | BG24: =AU$5 | BI24: =DATE(BI$5,1,1) | BJ24: =DATE(BI$5,2,1) | BK24: =DATE(BI$5,3,1) | BL24: =DATE(BI$5,4,1) | BM24: =DATE(BI$5,5,1) | BN24: =DATE(BI$5,6,1) | BO24: =DATE(BI$5,7,1) | BP24: =DATE(BI$5,8,1) | BQ24: =DATE(BI$5,9,1) | BR24: =DATE(BI$5,10,1) | BS24: =DATE(BI$5,11,1) | BT24: =DATE(BI$5,12,1) | BU24: =BI$5 | BW24: =DATE(BW$5,1,1) | BX24: =DATE(BW$5,2,1) | BY24: =DATE(BW$5,3,1) | BZ24: =DATE(BW$5,4,1) | CA24: =DATE(BW$5,5,1) | CB24: =DATE(BW$5,6,1) | CC24: =DATE(BW$5,7,1) | CD24: =DATE(BW$5,8,1) | CE24: =DATE(BW$5,9,1) | CF24: =DATE(BW$5,10,1) | CG24: =DATE(BW$5,11,1) | CH24: =DATE(BW$5,12,1) | CI24: =BW$5 | CK24: =DATE(CK$5,1,1) | CL24: =DATE(CK$5,2,1) | CM24: =DATE(CK$5,3,1) | CN24: =DATE(CK$5,4,1) | CO24: =DATE(CK$5,5,1) | CP24: =DATE(CK$5,6,1) | CQ24: =DATE(CK$5,7,1) | CR24: =DATE(CK$5,8,1) | CS24: =DATE(CK$5,9,1) | CT24: =DATE(CK$5,10,1) | CU24: =DATE(CK$5,11,1) | CV24: =DATE(CK$5,12,1) | CW24: =CK$5 | CY24: =DATE(CY$5,1,1) | CZ24: =DATE(CY$5,2,1) | DA24: =DATE(CY$5,3,1) | DB24: =DATE(CY$5,4,1) | DC24: =DATE(CY$5,5,1) | DD24: =DATE(CY$5,6,1) | DE24: =DATE(CY$5,7,1) | DF24: =DATE(CY$5,8,1) | DG24: =DATE(CY$5,9,1) | DH24: =DATE(CY$5,10,1) | DI24: =DATE(CY$5,11,1) | DJ24: =DATE(CY$5,12,1) | DK24: =CY$5 | DM24: =DATE(DM$5,1,1) | DN24: =DATE(DM$5,2,1) | DO24: =DATE(DM$5,3,1) | DP24: =DATE(DM$5,4,1) | DQ24: =DATE(DM$5,5,1) | DR24: =DATE(DM$5,6,1) | DS24: =DATE(DM$5,7,1) | DT24: =DATE(DM$5,8,1) | DU24: =DATE(DM$5,9,1) | DV24: =DATE(DM$5,10,1) | DW24: =DATE(DM$5,11,1) | DX24: =DATE(DM$5,12,1) | DY24: =DM$5 | EA24: =DATE(EA$5,1,1) | EB24: =DATE(EA$5,2,1) | EC24: =DATE(EA$5,3,1) | ED24: =DATE(EA$5,4,1) | EE24: =DATE(EA$5,5,1) | EF24: =DATE(EA$5,6,1) | EG24: =DATE(EA$5,7,1) | EH24: =DATE(EA$5,8,1) | EI24: =DATE(EA$5,9,1) | EJ24: =DATE(EA$5,10,1) | EK24: =DATE(EA$5,11,1) | EL24: =DATE(EA$5,12,1) | EM24: =EA$5
C25: Rent | Q25: =SUM(E25:P25) | S25: 1500 | AE25: =SUM(S25:AD25) | AS25: =SUM(AG25:AR25) | BG25: =SUM(AU25:BF25) | BU25: =SUM(BI25:BT25) | CI25: =SUM(BW25:CH25) | CW25: =SUM(CK25:CV25) | DK25: =SUM(CY25:DJ25) | DY25: =SUM(DM25:DX25) | EM25: =SUM(EA25:EL25)
C26: Food | Q26: =SUM(E26:P26) | AE26: =SUM(S26:AD26) | AS26: =SUM(AG26:AR26) | BG26: =SUM(AU26:BF26) | BU26: =SUM(BI26:BT26) | CI26: =SUM(BW26:CH26) | CW26: =SUM(CK26:CV26) | DK26: =SUM(CY26:DJ26) | DY26: =SUM(DM26:DX26) | EM26: =SUM(EA26:EL26)
C27: Subscription | Q27: =SUM(E27:P27) | AE27: =SUM(S27:AD27)
C28: ne | Q28: =SUM(E28:P28) | AE28: =SUM(S28:AD28) | AS28: =SUM(AG28:AR28) | BG28: =SUM(AU28:BF28) | BU28: =SUM(BI28:BT28) | CI28: =SUM(BW28:CH28) | CW28: =SUM(CK28:CV28) | DK28: =SUM(CY28:DJ28) | DY28: =SUM(DM28:DX28) | EM28: =SUM(EA28:EL28)
C29: ha | Q29: =SUM(E29:P29) | AE29: =SUM(S29:AD29)
C30: lo | Q30: =SUM(E30:P30) | AE30: =SUM(S30:AD30)
C31: ki | Q31: =SUM(E31:P31) | AE31: =SUM(S31:AD31)
C32: ji | Q32: =SUM(E32:P32) | AE32: =SUM(S32:AD32)
C33: wi | Q33: =SUM(E33:P33) | AE33: =SUM(S33:AD33)
C34: oi | Q34: =SUM(E34:P34) | AE34: =SUM(S34:AD34) | AS34: =SUM(AG34:AR34) | BG34: =SUM(AU34:BF34) | BU34: =SUM(BI34:BT34) | CI34: =SUM(BW34:CH34) | CW34: =SUM(CK34:CV34) | DK34: =SUM(CY34:DJ34) | DY34: =SUM(DM34:DX34) | EM34: =SUM(EA34:EL34)
Q35: =SUM(E35:P35) | AE35: =SUM(S35:AD35) | AS35: =SUM(AG35:AR35) | BG35: =SUM(AU35:BF35) | BU35: =SUM(BI35:BT35) | CI35: =SUM(BW35:CH35) | CW35: =SUM(CK35:CV35) | DK35: =SUM(CY35:DJ35) | DY35: =SUM(DM35:DX35) | EM35: =SUM(EA35:EL35)
Q36: =SUM(E36:P36) | AE36: =SUM(S36:AD36)
Q37: =SUM(E37:P37) | AE37: =SUM(S37:AD37) | AS37: =SUM(AG37:AR37) | BG37: =SUM(AU37:BF37) | BU37: =SUM(BI37:BT37) | CI37: =SUM(BW37:CH37) | CW37: =SUM(CK37:CV37) | DK37: =SUM(CY37:DJ37) | DY37: =SUM(DM37:DX37) | EM37: =SUM(EA37:EL37)
Q38: =SUM(E38:P38) | AE38: =SUM(S38:AD38)
Q39: =SUM(E39:P39) | AE39: =SUM(S39:AD39)
Q40: =SUM(E40:P40) | AE40: =SUM(S40:AD40)
Q41: =SUM(E41:P41) | AE41: =SUM(S41:AD41)
Q42: =SUM(E42:P42) | AE42: =SUM(S42:AD42)
Q43: =SUM(E43:P43) | AE43: =SUM(S43:AD43)
Q44: =SUM(E44:P44) | AE44: =SUM(S44:AD44)
Q45: =SUM(E45:P45) | AE45: =SUM(S45:AD45)
...

Sheet Budget Tracking
B1: Budget Tracking
C11: Date | D11: Type | E11: Category | F11: Amount | G11: Details | H11: Balance | I11: Effective Date
C12: 45658 | I12: =IF(AND(tracking[[#This Row],[Type]]="Income", shift_late_income_status="Active", DAY(tracking[[#This Row],[Date]])>=shift_late_income_starting_day), DATE(YEAR(tracking[[#This Row],[Date]]), MONTH(tracking[[#This Row],[Date]])+1, 1), tracking[[#This Row],[Date]])
I13: =IF(AND(tracking[[#This Row],[Type]]="Income", shift_late_income_status="Active", DAY(tracking[[#This Row],[Date]])>=shift_late_income_starting_day), DATE(YEAR(tracking[[#This Row],[Date]]), MONTH(tracking[[#This Row],[Date]])+1, 1), tracking[[#This Row],[Date]])
I14: =IF(AND(tracking[[#This Row],[Type]]="Income", shift_late_income_status="Active", DAY(tracking[[#This Row],[Date]])>=shift_late_income_starting_day), DATE(YEAR(tracking[[#This Row],[Date]]), MONTH(tracking[[#This Row],[Date]])+1, 1), tracking[[#This Row],[Date]])
I15: =IF(AND(tracking[[#This Row],[Type]]="Income", shift_late_income_status="Active", DAY(tracking[[#This Row],[Date]])>=shift_late_income_starting_day), DATE(YEAR(tracking[[#This Row],[Date]]), MONTH(tracking[[#This Row],[Date]])+1, 1), tracking[[#This Row],[Date]])
I16: =IF(AND(tracking[[#This Row],[Type]]="Income", shift_late_income_status="Active", DAY(tracking[[#This Row],[Date]])>=shift_late_income_starting_day), DATE(YEAR(tracking[[#This Row],[Date]]), MONTH(tracking[[#This Row],[Date]])+1, 1), tracking[[#This Row],[Date]])
I17: =IF(AND(tracking[[#This Row],[Type]]="Income", shift_late_income_status="Active", DAY(tracking[[#This Row],[Date]])>=shift_late_income_starting_day), DATE(YEAR(tracking[[#This Row],[Date]]), MONTH(tracking[[#This Row],[Date]])+1, 1), tracking[[#This Row],[Date]])
I18: =IF(AND(tracking[[#This Row],[Type]]="Income", shift_late_income_status="Active", DAY(tracking[[#This Row],[Date]])>=shift_late_income_starting_day), DATE(YEAR(tracking[[#This Row],[Date]]), MONTH(tracking[[#This Row],[Date]])+1, 1), tracking[[#This Row],[Date]])
I19: =IF(AND(tracking[[#This Row],[Type]]="Income", shift_late_income_status="Active", DAY(tracking[[#This Row],[Date]])>=shift_late_income_starting_day), DATE(YEAR(tracking[[#This Row],[Date]]), MONTH(tracking[[#This Row],[Date]])+1, 1), tracking[[#This Row],[Date]])
I20: =IF(AND(tracking[[#This Row],[Type]]="Income", shift_late_income_status="Active", DAY(tracking[[#This Row],[Date]])>=shift_late_income_starting_day), DATE(YEAR(tracking[[#This Row],[Date]]), MONTH(tracking[[#This Row],[Date]])+1, 1), tracking[[#This Row],[Date]])
I21: =IF(AND(tracking[[#This Row],[Type]]="Income", shift_late_income_status="Active", DAY(tracking[[#This Row],[Date]])>=shift_late_income_starting_day), DATE(YEAR(tracking[[#This Row],[Date]]), MONTH(tracking[[#This Row],[Date]])+1, 1), tracking[[#This Row],[Date]])
I22: =IF(AND(tracking[[#This Row],[Type]]="Income", shift_late_income_status="Active", DAY(tracking[[#This Row],[Date]])>=shift_late_income_starting_day), DATE(YEAR(tracking[[#This Row],[Date]]), MONTH(tracking[[#This Row],[Date]])+1, 1), tracking[[#This Row],[Date]])
I23: =IF(AND(tracking[[#This Row],[Type]]="Income", shift_late_income_status="Active", DAY(tracking[[#This Row],[Date]])>=shift_late_income_starting_day), DATE(YEAR(tracking[[#This Row],[Date]]), MONTH(tracking[[#This Row],[Date]])+1, 1), tracking[[#This Row],[Date]])
I24: =IF(AND(tracking[[#This Row],[Type]]="Income", shift_late_income_status="Active", DAY(tracking[[#This Row],[Date]])>=shift_late_income_starting_day), DATE(YEAR(tracking[[#This Row],[Date]]), MONTH(tracking[[#This Row],[Date]])+1, 1), tracking[[#This Row],[Date]])
... I226: =IF(AND(tracking[[#This Row],[Type]]="Income", shift_late_income_status="Active", DAY(tracking[[#This Row],[Date]])>=shift_late_income_starting_day), DATE(YEAR(tracking[[#This Row],[Date]]), MONTH(tracking[[#This Row],[Date]])+1, 1), tracking[[#This Row],[Date]])

Sheet Budget Dashboard
Y3: ‚
AQ5: Year
AN6: Select the year to view → | AQ6: 2025
AQ8: Period
AN9: Select the period to view → | AQ9: Current Month
Y11: ="Breakdown - " & IF(selected_period="Total Year", selected_year & " " & "(Total Year)", selected_period_display & " " & selected_year) | AF11: ="Summary - " & IF(selected_period="Total Year", selected_year & " " & "(Total Year)", selected_period_display & " " & selected_year)
C12: row_id | D12: header_row_id | E12: is_header | F12: is_cat | G12: is_total | H12: is_empty | I12: type | J12: item | K12: tracked | L12: budget | M12: sort_min_row | N12: sort_max_row | O12: tracked_range | P12: tracked_rank | Q12: budget_range | R12: budget_rank | S12: comb_rank | T12: comb_rank_range | U12: comb_rank_norm | V12: comb_rank_norm_run_range | W12: comb_rank_unique | X12: sorted_row_id (Lookup)
C13: {=income_header_row} | D13: =IF(is_header, row_id, IF(NOT(is_empty), D12, -1)) | E13: {=OR(row_id=income_header_row, row_id=expenses_header_row, row_id=savings_header_row) * 1} | F13: =1 * NOT(OR(is_header, is_total, is_empty)) | G13: {=OR(row_id=income_total_row, row_id=expenses_total_row, row_id=savings_total_row) * 1} | H13: =OR(row_id="/1", row_id="/2", row_id=-1)*1 | I13: {=IFERROR(INDEX('Budget Planning'!$C:$C, header_row_id), "")} | J13: {=IFERROR(INDEX('Budget Planning'!$C:$C, row_id), "")} | K13: {=IF(OR(is_header, is_empty), "", IF(is_total, IF(selected_period="Total Year", SUM(tracking[Amount] * (tracking[Type]=type) * (YEAR(tracking[Effective Date])=selected_year)), SUM(tracking[Amount] * (tracking[Type]=type) * (YEAR(tracking[Effective Date])=selected_year) * (MONTH(tracking[Effective Date])=selected_period))), IF(selected_period="Total Year", SUM(tracking[Amount] * (tracking[Type]=type) * (tracking[Category]=item) * (YEAR(tracking[Effective Date])=selected_year)), SUM(tracking[Amount] * (tracking[Type]=type) * (tracking[Category]=item) * (YEAR(tracking[Effective Date])=selected_year) * (MONTH(tracking[Effective Date])=selected_period)))))} | L13: {=IF(OR(is_header, is_empty), "", INDEX('Budget Planning'!$E:$EM, row_id, MATCH(IF(selected_period="Total Year", selected_year, DATE(selected_year, selected_period, 1)), 'Budget Planning'!$E$9:$EM$9, 0)))} | M13: {=IF(is_cat, IF(header_row_id=income_header_row, MATCH(income_min_row, $C:$C, 0), IF(header_row_id=expenses_header_row, MATCH(expenses_min_row, $C:$C, 0), IF(header_row_id=savings_header_row, MATCH(savings_min_row, $C:$C, 0), ""))), "")} | N13: {=IF(is_cat, IF(header_row_id=income_header_row, MATCH(income_max_row, $C:$C, 0), IF(header_row_id=expenses_header_row, MATCH(expenses_max_row, $C:$C, 0), IF(header_row_id=savings_header_row, MATCH(savings_max_row, $C:$C, 0), ""))), "")} | O13: =IF(is_cat, ADDRESS(sort_min_row, COLUMN(tracked)) & ":" & ADDRESS(sort_max_row, COLUMN(tracked)), "") | P13: =IF(is_cat, RANK(tracked, INDIRECT(tracked_range), 0), "") | Q13: =IF(is_cat, ADDRESS(sort_min_row, COLUMN(budget)) & ":" & ADDRESS(sort_max_row, COLUMN(budget)), "") | R13: =IF(is_cat, RANK(budget, INDIRECT(budget_range), 0), "") | S13: =IF(is_cat, _xlfn.NUMBERVALUE(tracked_rank & budget_rank), "") | T13: =IF(is_cat, ADDRESS(sort_min_row, COLUMN(comb_rank)) & ":" & ADDRESS(sort_max_row, COLUMN(comb_rank)), "") | U13: =IF(is_cat, RANK(comb_rank, INDIRECT(comb_rank_range), 1), "") | V13: =IF(is_cat, ADDRESS(sort_min_row, COLUMN(comb_rank_norm)) & ":" & ADDRESS(ROW(), COLUMN(comb_rank_norm)), "") | W13: =IF(is_cat, comb_rank_norm + COUNTIF(INDIRECT(comb_rank_norm_run_range), comb_rank_norm)-1, "") | X13: =IF(is_cat, header_row_id + comb_rank_unique, row_id) | Y13: =IF(is_empty, "", INDEX($J:$J, MATCH(row_id, $X:$X, 0))) | Z13: =IF(is_empty, "", IF(is_header, "Tracked", INDEX($K:$K, MATCH(row_id, $X:$X, 0)))) | AA13: =IF(is_empty, "", IF(is_header, "Budget", INDEX($L:$L, MATCH(row_id, $X:$X, 0)))) | AB13: =IF(is_empty, "", IF(is_header, "% Compl.", IFERROR(out_tracked / out_budget, "-"))) | AC13: =IF(is_empty, "", IF(is_header, "Remaining", IF(out_budget - out_tracked > 0, out_budget - out_tracked, 0))) | AD13: =IF(is_empty, "", IF(is_header, "Excess", IF(out_budget - out_tracked < 0, out_tracked - out_budget, 0)))
C14: {=IF(C13=-1,-1, IF(C13<income_max_row,C13+1, IF(C13=income_max_row,income_total_row, IF(C13=income_total_row,"/1", IF(C13="/1",expenses_header_row, IF(C13<expenses_max_row,C13+1, IF(C13=expenses_max_row,expenses_total_row, IF(C13=expenses_total_row, "/2", IF(C13="/2", savings_header_row, IF(C13<savings_max_row, C13+1, IF(C13=savings_max_row, savings_total_row, -1)))))))))))} | D14: =IF(is_header, row_id, IF(NOT(is_empty), D13, -1)) | E14: {=OR(row_id=income_header_row, row_id=expenses_header_row, row_id=savings_header_row) * 1} | F14: =1 * NOT(OR(is_header, is_total, is_empty)) | G14: {=OR(row_id=income_total_row, row_id=expenses_total_row, row_id=savings_total_row) * 1} | H14: =OR(row_id="/1", row_id="/2", row_id=-1)*1 | I14: {=IFERROR(INDEX('Budget Planning'!$C:$C, header_row_id), "")} | J14: {=IFERROR(INDEX('Budget Planning'!$C:$C, row_id), "")} | K14: {=IF(OR(is_header, is_empty), "", IF(is_total, IF(selected_period="Total Year", SUM(tracking[Amount] * (tracking[Type]=type) * (YEAR(tracking[Effective Date])=selected_year)), SUM(tracking[Amount] * (tracking[Type]=type) * (YEAR(tracking[Effective Date])=selected_year) * (MONTH(tracking[Effective Date])=selected_period))), IF(selected_period="Total Year", SUM(tracking[Amount] * (tracking[Type]=type) * (tracking[Category]=item) * (YEAR(tracking[Effective Date])=selected_year)), SUM(tracking[Amount] * (tracking[Type]=type) * (tracking[Category]=item) * (YEAR(tracking[Effective Date])=selected_year) * (MONTH(tracking[Effective Date])=selected_period)))))} | L14: {=IF(OR(is_header, is_empty), "", INDEX('Budget Planning'!$E:$EM, row_id, MATCH(IF(selected_period="Total Year", selected_year, DATE(selected_year, selected_period, 1)), 'Budget Planning'!$E$9:$EM$9, 0)))} | M14: {=IF(is_cat, IF(header_row_id=income_header_row, MATCH(income_min_row, $C:$C, 0), IF(header_row_id=expenses_header_row, MATCH(expenses_min_row, $C:$C, 0), IF(header_row_id=savings_header_row, MATCH(savings_min_row, $C:$C, 0), ""))), "")} | N14: {=IF(is_cat, IF(header_row_id=income_header_row, MATCH(income_max_row, $C:$C, 0), IF(header_row_id=expenses_header_row, MATCH(expenses_max_row, $C:$C, 0), IF(header_row_id=savings_header_row, MATCH(savings_max_row, $C:$C, 0), ""))), "")} | O14: =IF(is_cat, ADDRESS(sort_min_row, COLUMN(tracked)) & ":" & ADDRESS(sort_max_row, COLUMN(tracked)), "") | P14: =IF(is_cat, RANK(tracked, INDIRECT(tracked_range), 0), "") | Q14: =IF(is_cat, ADDRESS(sort_min_row, COLUMN(budget)) & ":" & ADDRESS(sort_max_row, COLUMN(budget)), "") | R14: =IF(is_cat, RANK(budget, INDIRECT(budget_range), 0), "") | S14: =IF(is_cat, _xlfn.NUMBERVALUE(tracked_rank & budget_rank), "") | T14: =IF(is_cat, ADDRESS(sort_min_row, COLUMN(comb_rank)) & ":" & ADDRESS(sort_max_row, COLUMN(comb_rank)), "") | U14: =IF(is_cat, RANK(comb_rank, INDIRECT(comb_rank_range), 1), "") | V14: =IF(is_cat, ADDRESS(sort_min_row, COLUMN(comb_rank_norm)) & ":" & ADDRESS(ROW(), COLUMN(comb_rank_norm)), "") | W14: =IF(is_cat, comb_rank_norm + COUNTIF(INDIRECT(comb_rank_norm_run_range), comb_rank_norm)-1, "") | X14: =IF(is_cat, header_row_id + comb_rank_unique, row_id) | Y14: =IF(is_empty, "", INDEX($J:$J, MATCH(row_id, $X:$X, 0))) | Z14: =IF(is_empty, "", IF(is_header, "Tracked", INDEX($K:$K, MATCH(row_id, $X:$X, 0)))) | AA14: =IF(is_empty, "", IF(is_header, "Budget", INDEX($L:$L, MATCH(row_id, $X:$X, 0)))) | AB14: =IF(is_empty, "", IF(is_header, "% Compl.", IFERROR(out_tracked / out_budget, "-"))) | AC14: =IF(is_empty, "", IF(is_header, "Remaining", IF(out_budget - out_tracked > 0, out_budget - out_tracked, 0))) | AD14: =IF(is_empty, "", IF(is_header, "Excess", IF(out_budget - out_tracked < 0, out_tracked - out_budget, 0)))
C15: {=IF(C14=-1,-1, IF(C14<income_max_row,C14+1, IF(C14=income_max_row,income_total_row, IF(C14=income_total_row,"/1", IF(C14="/1",expenses_header_row, IF(C14<expenses_max_row,C14+1, IF(C14=expenses_max_row,expenses_total_row, IF(C14=expenses_total_row, "/2", IF(C14="/2", savings_header_row, IF(C14<savings_max_row, C14+1, IF(C14=savings_max_row, savings_total_row, -1)))))))))))} | D15: =IF(is_header, row_id, IF(NOT(is_empty), D14, -1)) | E15: {=OR(row_id=income_header_row, row_id=expenses_header_row, row_id=savings_header_row) * 1} | F15: =1 * NOT(OR(is_header, is_total, is_empty)) | G15: {=OR(row_id=income_total_row, row_id=expenses_total_row, row_id=savings_total_row) * 1} | H15: =OR(row_id="/1", row_id="/2", row_id=-1)*1 | I15: {=IFERROR(INDEX('Budget Planning'!$C:$C, header_row_id), "")} | J15: {=IFERROR(INDEX('Budget Planning'!$C:$C, row_id), "")} | K15: {=IF(OR(is_header, is_empty), "", IF(is_total, IF(selected_period="Total Year", SUM(tracking[Amount] * (tracking[Type]=type) * (YEAR(tracking[Effective Date])=selected_year)), SUM(tracking[Amount] * (tracking[Type]=type) * (YEAR(tracking[Effective Date])=selected_year) * (MONTH(tracking[Effective Date])=selected_period))), IF(selected_period="Total Year", SUM(tracking[Amount] * (tracking[Type]=type) * (tracking[Category]=item) * (YEAR(tracking[Effective Date])=selected_year)), SUM(tracking[Amount] * (tracking[Type]=type) * (tracking[Category]=item) * (YEAR(tracking[Effective Date])=selected_year) * (MONTH(tracking[Effective Date])=selected_period)))))} | L15: {=IF(OR(is_header, is_empty), "", INDEX('Budget Planning'!$E:$EM, row_id, MATCH(IF(selected_period="Total Year", selected_year, DATE(selected_year, selected_period, 1)), 'Budget Planning'!$E$9:$EM$9, 0)))} | M15: {=IF(is_cat, IF(header_row_id=income_header_row, MATCH(income_min_row, $C:$C, 0), IF(header_row_id=expenses_header_row, MATCH(expenses_min_row, $C:$C, 0), IF(header_row_id=savings_header_row, MATCH(savings_min_row, $C:$C, 0), ""))), "")} | N15: {=IF(is_cat, IF(header_row_id=income_header_row, MATCH(income_max_row, $C:$C, 0), IF(header_row_id=expenses_header_row, MATCH(expenses_max_row, $C:$C, 0), IF(header_row_id=savings_header_row, MATCH(savings_max_row, $C:$C, 0), ""))), "")} | O15: =IF(is_cat, ADDRESS(sort_min_row, COLUMN(tracked)) & ":" & ADDRESS(sort_max_row, COLUMN(tracked)), "") | P15: =IF(is_cat, RANK(tracked, INDIRECT(tracked_range), 0), "") | Q15: =IF(is_cat, ADDRESS(sort_min_row, COLUMN(budget)) & ":" & ADDRESS(sort_max_row, COLUMN(budget)), "") | R15: =IF(is_cat, RANK(budget, INDIRECT(budget_range), 0), "") | S15: =IF(is_cat, _xlfn.NUMBERVALUE(tracked_rank & budget_rank), "") | T15: =IF(is_cat, ADDRESS(sort_min_row, COLUMN(comb_rank)) & ":" & ADDRESS(sort_max_row, COLUMN(comb_rank)), "") | U15: =IF(is_cat, RANK(comb_rank, INDIRECT(comb_rank_range), 1), "") | V15: =IF(is_cat, ADDRESS(sort_min_row, COLUMN(comb_rank_norm)) & ":" & ADDRESS(ROW(), COLUMN(comb_rank_norm)), "") | W15: =IF(is_cat, comb_rank_norm + COUNTIF(INDIRECT(comb_rank_norm_run_range), comb_rank_norm)-1, "") | X15: =IF(is_cat, header_row_id + comb_rank_unique, row_id) | Y15: =IF(is_empty, "", INDEX($J:$J, MATCH(row_id, $X:$X, 0))) | Z15: =IF(is_empty, "", IF(is_header, "Tracked", INDEX($K:$K, MATCH(row_id, $X:$X, 0)))) | AA15: =IF(is_empty, "", IF(is_header, "Budget", INDEX($L:$L, MATCH(row_id, $X:$X, 0)))) | AB15: =IF(is_empty, "", IF(is_header, "% Compl.", IFERROR(out_tracked / out_budget, "-"))) | AC15: =IF(is_empty, "", IF(is_header, "Remaining", IF(out_budget - out_tracked > 0, out_budget - out_tracked, 0))) | AD15: =IF(is_empty, "", IF(is_header, "Excess", IF(out_budget - out_tracked < 0, out_tracked - out_budget, 0)))
C16: {=IF(C15=-1,-1, IF(C15<income_max_row,C15+1, IF(C15=income_max_row,income_total_row, IF(C15=income_total_row,"/1", IF(C15="/1",expenses_header_row, IF(C15<expenses_max_row,C15+1, IF(C15=expenses_max_row,expenses_total_row, IF(C15=expenses_total_row, "/2", IF(C15="/2", savings_header_row, IF(C15<savings_max_row, C15+1, IF(C15=savings_max_row, savings_total_row, -1)))))))))))} | D16: =IF(is_header, row_id, IF(NOT(is_empty), D15, -1)) | E16: {=OR(row_id=income_header_row, row_id=expenses_header_row, row_id=savings_header_row) * 1} | F16: =1 * NOT(OR(is_header, is_total, is_empty)) | G16: {=OR(row_id=income_total_row, row_id=expenses_total_row, row_id=savings_total_row) * 1} | H16: =OR(row_id="/1", row_id="/2", row_id=-1)*1 | I16: {=IFERROR(INDEX('Budget Planning'!$C:$C, header_row_id), "")} | J16: {=IFERROR(INDEX('Budget Planning'!$C:$C, row_id), "")} | K16: {=IF(OR(is_header, is_empty), "", IF(is_total, IF(selected_period="Total Year", SUM(tracking[Amount] * (tracking[Type]=type) * (YEAR(tracking[Effective Date])=selected_year)), SUM(tracking[Amount] * (tracking[Type]=type) * (YEAR(tracking[Effective Date])=selected_year) * (MONTH(tracking[Effective Date])=selected_period))), IF(selected_period="Total Year", SUM(tracking[Amount] * (tracking[Type]=type) * (tracking[Category]=item) * (YEAR(tracking[Effective Date])=selected_year)), SUM(tracking[Amount] * (tracking[Type]=type) * (tracking[Category]=item) * (YEAR(tracking[Effective Date])=selected_year) * (MONTH(tracking[Effective Date])=selected_period)))))} | L16: {=IF(OR(is_header, is_empty), "", INDEX('Budget Planning'!$E:$EM, row_id, MATCH(IF(selected_period="Total Year", selected_year, DATE(selected_year, selected_period, 1)), 'Budget Planning'!$E$9:$EM$9, 0)))} | M16: {=IF(is_cat, IF(header_row_id=income_header_row, MATCH(income_min_row, $C:$C, 0), IF(header_row_id=expenses_header_row, MATCH(expenses_min_row, $C:$C, 0), IF(header_row_id=savings_header_row, MATCH(savings_min_row, $C:$C, 0), ""))), "")} | N16: {=IF(is_cat, IF(header_row_id=income_header_row, MATCH(income_max_row, $C:$C, 0), IF(header_row_id=expenses_header_row, MATCH(expenses_max_row, $C:$C, 0), IF(header_row_id=savings_header_row, MATCH(savings_max_row, $C:$C, 0), ""))), "")} | O16: =IF(is_cat, ADDRESS(sort_min_row, COLUMN(tracked)) & ":" & ADDRESS(sort_max_row, COLUMN(tracked)), "") | P16: =IF(is_cat, RANK(tracked, INDIRECT(tracked_range), 0), "") | Q16: =IF(is_cat, ADDRESS(sort_min_row, COLUMN(budget)) & ":" & ADDRESS(sort_max_row, COLUMN(budget)), "") | R16: =IF(is_cat, RANK(budget, INDIRECT(budget_range), 0), "") | S16: =IF(is_cat, _xlfn.NUMBERVALUE(tracked_rank & budget_rank), "") | T16: =IF(is_cat, ADDRESS(sort_min_row, COLUMN(comb_rank)) & ":" & ADDRESS(sort_max_row, COLUMN(comb_rank)), "") | U16: =IF(is_cat, RANK(comb_rank, INDIRECT(comb_rank_range), 1), "") | V16: =IF(is_cat, ADDRESS(sort_min_row, COLUMN(comb_rank_norm)) & ":" & ADDRESS(ROW(), COLUMN(comb_rank_norm)), "") | W16: =IF(is_cat, comb_rank_norm + COUNTIF(INDIRECT(comb_rank_norm_run_range), comb_rank_norm)-1, "") | X16: =IF(is_cat, header_row_id + comb_rank_unique, row_id) | Y16: =IF(is_empty, "", INDEX($J:$J, MATCH(row_id, $X:$X, 0))) | Z16: =IF(is_empty, "", IF(is_header, "Tracked", INDEX($K:$K, MATCH(row_id, $X:$X, 0)))) | AA16: =IF(is_empty, "", IF(is_header, "Budget", INDEX($L:$L, MATCH(row_id, $X:$X, 0)))) | AB16: =IF(is_empty, "", IF(is_header, "% Compl.", IFERROR(out_tracked / out_budget, "-"))) | AC16: =IF(is_empty, "", IF(is_header, "Remaining", IF(out_budget - out_tracked > 0, out_budget - out_tracked, 0))) | AD16: =IF(is_empty, "", IF(is_header, "Excess", IF(out_budget - out_tracked < 0, out_tracked - out_budget, 0))) | AI16: =Calculation!E35 | AJ16: =Calculation!F35
C17: {=IF(C16=-1,-1, IF(C16<income_max_row,C16+1, IF(C16=income_max_row,income_total_row, IF(C16=income_total_row,"/1", IF(C16="/1",expenses_header_row, IF(C16<expenses_max_row,C16+1, IF(C16=expenses_max_row,expenses_total_row, IF(C16=expenses_total_row, "/2", IF(C16="/2", savings_header_row, IF(C16<savings_max_row, C16+1, IF(C16=savings_max_row, savings_total_row, -1)))))))))))} | D17: =IF(is_header, row_id, IF(NOT(is_empty), D16, -1)) | E17: {=OR(row_id=income_header_row, row_id=expenses_header_row, row_id=savings_header_row) * 1} | F17: =1 * NOT(OR(is_header, is_total, is_empty)) | G17: {=OR(row_id=income_total_row, row_id=expenses_total_row, row_id=savings_total_row) * 1} | H17: =OR(row_id="/1", row_id="/2", row_id=-1)*1 | I17: {=IFERROR(INDEX('Budget Planning'!$C:$C, header_row_id), "")} | J17: {=IFERROR(INDEX('Budget Planning'!$C:$C, row_id), "")} | K17: {=IF(OR(is_header, is_empty), "", IF(is_total, IF(selected_period="Total Year", SUM(tracking[Amount] * (tracking[Type]=type) * (YEAR(tracking[Effective Date])=selected_year)), SUM(tracking[Amount] * (tracking[Type]=type) * (YEAR(tracking[Effective Date])=selected_year) * (MONTH(tracking[Effective Date])=selected_period))), IF(selected_period="Total Year", SUM(tracking[Amount] * (tracking[Type]=type) * (tracking[Category]=item) * (YEAR(tracking[Effective Date])=selected_year)), SUM(tracking[Amount] * (tracking[Type]=type) * (tracking[Category]=item) * (YEAR(tracking[Effective Date])=selected_year) * (MONTH(tracking[Effective Date])=selected_period)))))} | L17: {=IF(OR(is_header, is_empty), "", INDEX('Budget Planning'!$E:$EM, row_id, MATCH(IF(selected_period="Total Year", selected_year, DATE(selected_year, selected_period, 1)), 'Budget Planning'!$E$9:$EM$9, 0)))} | M17: {=IF(is_cat, IF(header_row_id=income_header_row, MATCH(income_min_row, $C:$C, 0), IF(header_row_id=expenses_header_row, MATCH(expenses_min_row, $C:$C, 0), IF(header_row_id=savings_header_row, MATCH(savings_min_row, $C:$C, 0), ""))), "")} | N17: {=IF(is_cat, IF(header_row_id=income_header_row, MATCH(income_max_row, $C:$C, 0), IF(header_row_id=expenses_header_row, MATCH(expenses_max_row, $C:$C, 0), IF(header_row_id=savings_header_row, MATCH(savings_max_row, $C:$C, 0), ""))), "")} | O17: =IF(is_cat, ADDRESS(sort_min_row, COLUMN(tracked)) & ":" & ADDRESS(sort_max_row, COLUMN(tracked)), "") | P17: =IF(is_cat, RANK(tracked, INDIRECT(tracked_range), 0), "") | Q17: =IF(is_cat, ADDRESS(sort_min_row, COLUMN(budget)) & ":" & ADDRESS(sort_max_row, COLUMN(budget)), "") | R17: =IF(is_cat, RANK(budget, INDIRECT(budget_range), 0), "") | S17: =IF(is_cat, _xlfn.NUMBERVALUE(tracked_rank & budget_rank), "") | T17: =IF(is_cat, ADDRESS(sort_min_row, COLUMN(comb_rank)) & ":" & ADDRESS(sort_max_row, COLUMN(comb_rank)), "") | U17: =IF(is_cat, RANK(comb_rank, INDIRECT(comb_rank_range), 1), "") | V17: =IF(is_cat, ADDRESS(sort_min_row, COLUMN(comb_rank_norm)) & ":" & ADDRESS(ROW(), COLUMN(comb_rank_norm)), "") | W17: =IF(is_cat, comb_rank_norm + COUNTIF(INDIRECT(comb_rank_norm_run_range), comb_rank_norm)-1, "") | X17: =IF(is_cat, header_row_id + comb_rank_unique, row_id) | Y17: =IF(is_empty, "", INDEX($J:$J, MATCH(row_id, $X:$X, 0))) | Z17: =IF(is_empty, "", IF(is_header, "Tracked", INDEX($K:$K, MATCH(row_id, $X:$X, 0)))) | AA17: =IF(is_empty, "", IF(is_header, "Budget", INDEX($L:$L, MATCH(row_id, $X:$X, 0)))) | AB17: =IF(is_empty, "", IF(is_header, "% Compl.", IFERROR(out_tracked / out_budget, "-"))) | AC17: =IF(is_empty, "", IF(is_header, "Remaining", IF(out_budget - out_tracked > 0, out_budget - out_tracked, 0))) | AD17: =IF(is_empty, "", IF(is_header, "Excess", IF(out_budget - out_tracked < 0, out_tracked - out_budget, 0))) | AI17: =Calculation!E36 | AJ17: =Calculation!F36
C18: {=IF(C17=-1,-1, IF(C17<income_max_row,C17+1, IF(C17=income_max_row,income_total_row, IF(C17=income_total_row,"/1", IF(C17="/1",expenses_header_row, IF(C17<expenses_max_row,C17+1, IF(C17=expenses_max_row,expenses_total_row, IF(C17=expenses_total_row, "/2", IF(C17="/2", savings_header_row, IF(C17<savings_max_row, C17+1, IF(C17=savings_max_row, savings_total_row, -1)))))))))))} | D18: =IF(is_header, row_id, IF(NOT(is_empty), D17, -1)) | E18: {=OR(row_id=income_header_row, row_id=expenses_header_row, row_id=savings_header_row) * 1} | F18: =1 * NOT(OR(is_header, is_total, is_empty)) | G18: {=OR(row_id=income_total_row, row_id=expenses_total_row, row_id=savings_total_row) * 1} | H18: =OR(row_id="/1", row_id="/2", row_id=-1)*1 | I18: {=IFERROR(INDEX('Budget Planning'!$C:$C, header_row_id), "")} | J18: {=IFERROR(INDEX('Budget Planning'!$C:$C, row_id), "")} | K18: {=IF(OR(is_header, is_empty), "", IF(is_total, IF(selected_period="Total Year", SUM(tracking[Amount] * (tracking[Type]=type) * (YEAR(tracking[Effective Date])=selected_year)), SUM(tracking[Amount] * (tracking[Type]=type) * (YEAR(tracking[Effective Date])=selected_year) * (MONTH(tracking[Effective Date])=selected_period))), IF(selected_period="Total Year", SUM(tracking[Amount] * (tracking[Type]=type) * (tracking[Category]=item) * (YEAR(tracking[Effective Date])=selected_year)), SUM(tracking[Amount] * (tracking[Type]=type) * (tracking[Category]=item) * (YEAR(tracking[Effective Date])=selected_year) * (MONTH(tracking[Effective Date])=selected_period)))))} | L18: {=IF(OR(is_header, is_empty), "", INDEX('Budget Planning'!$E:$EM, row_id, MATCH(IF(selected_period="Total Year", selected_year, DATE(selected_year, selected_period, 1)), 'Budget Planning'!$E$9:$EM$9, 0)))} | M18: {=IF(is_cat, IF(header_row_id=income_header_row, MATCH(income_min_row, $C:$C, 0), IF(header_row_id=expenses_header_row, MATCH(expenses_min_row, $C:$C, 0), IF(header_row_id=savings_header_row, MATCH(savings_min_row, $C:$C, 0), ""))), "")} | N18: {=IF(is_cat, IF(header_row_id=income_header_row, MATCH(income_max_row, $C:$C, 0), IF(header_row_id=expenses_header_row, MATCH(expenses_max_row, $C:$C, 0), IF(header_row_id=savings_header_row, MATCH(savings_max_row, $C:$C, 0), ""))), "")} | O18: =IF(is_cat, ADDRESS(sort_min_row, COLUMN(tracked)) & ":" & ADDRESS(sort_max_row, COLUMN(tracked)), "") | P18: =IF(is_cat, RANK(tracked, INDIRECT(tracked_range), 0), "") | Q18: =IF(is_cat, ADDRESS(sort_min_row, COLUMN(budget)) & ":" & ADDRESS(sort_max_row, COLUMN(budget)), "") | R18: =IF(is_cat, RANK(budget, INDIRECT(budget_range), 0), "") | S18: =IF(is_cat, _xlfn.NUMBERVALUE(tracked_rank & budget_rank), "") | T18: =IF(is_cat, ADDRESS(sort_min_row, COLUMN(comb_rank)) & ":" & ADDRESS(sort_max_row, COLUMN(comb_rank)), "") | U18: =IF(is_cat, RANK(comb_rank, INDIRECT(comb_rank_range), 1), "") | V18: =IF(is_cat, ADDRESS(sort_min_row, COLUMN(comb_rank_norm)) & ":" & ADDRESS(ROW(), COLUMN(comb_rank_norm)), "") | W18: =IF(is_cat, comb_rank_norm + COUNTIF(INDIRECT(comb_rank_norm_run_range), comb_rank_norm)-1, "") | X18: =IF(is_cat, header_row_id + comb_rank_unique, row_id) | Y18: =IF(is_empty, "", INDEX($J:$J, MATCH(row_id, $X:$X, 0))) | Z18: =IF(is_empty, "", IF(is_header, "Tracked", INDEX($K:$K, MATCH(row_id, $X:$X, 0)))) | AA18: =IF(is_empty, "", IF(is_header, "Budget", INDEX($L:$L, MATCH(row_id, $X:$X, 0)))) | AB18: =IF(is_empty, "", IF(is_header, "% Compl.", IFERROR(out_tracked / out_budget, "-"))) | AC18: =IF(is_empty, "", IF(is_header, "Remaining", IF(out_budget - out_tracked > 0, out_budget - out_tracked, 0))) | AD18: =IF(is_empty, "", IF(is_header, "Excess", IF(out_budget - out_tracked < 0, out_tracked - out_budget, 0))) | AI18: =Calculation!E37 | AJ18: =Calculation!F37
C19: {=IF(C18=-1,-1, IF(C18<income_max_row,C18+1, IF(C18=income_max_row,income_total_row, IF(C18=income_total_row,"/1", IF(C18="/1",expenses_header_row, IF(C18<expenses_max_row,C18+1, IF(C18=expenses_max_row,expenses_total_row, IF(C18=expenses_total_row, "/2", IF(C18="/2", savings_header_row, IF(C18<savings_max_row, C18+1, IF(C18=savings_max_row, savings_total_row, -1)))))))))))} | D19: =IF(is_header, row_id, IF(NOT(is_empty), D18, -1)) | E19: {=OR(row_id=income_header_row, row_id=expenses_header_row, row_id=savings_header_row) * 1} | F19: =1 * NOT(OR(is_header, is_total, is_empty)) | G19: {=OR(row_id=income_total_row, row_id=expenses_total_row, row_id=savings_total_row) * 1} | H19: =OR(row_id="/1", row_id="/2", row_id=-1)*1 | I19: {=IFERROR(INDEX('Budget Planning'!$C:$C, header_row_id), "")} | J19: {=IFERROR(INDEX('Budget Planning'!$C:$C, row_id), "")} | K19: {=IF(OR(is_header, is_empty), "", IF(is_total, IF(selected_period="Total Year", SUM(tracking[Amount] * (tracking[Type]=type) * (YEAR(tracking[Effective Date])=selected_year)), SUM(tracking[Amount] * (tracking[Type]=type) * (YEAR(tracking[Effective Date])=selected_year) * (MONTH(tracking[Effective Date])=selected_period))), IF(selected_period="Total Year", SUM(tracking[Amount] * (tracking[Type]=type) * (tracking[Category]=item) * (YEAR(tracking[Effective Date])=selected_year)), SUM(tracking[Amount] * (tracking[Type]=type) * (tracking[Category]=item) * (YEAR(tracking[Effective Date])=selected_year) * (MONTH(tracking[Effective Date])=selected_period)))))} | L19: {=IF(OR(is_header, is_empty), "", INDEX('Budget Planning'!$E:$EM, row_id, MATCH(IF(selected_period="Total Year", selected_year, DATE(selected_year, selected_period, 1)), 'Budget Planning'!$E$9:$EM$9, 0)))} | M19: {=IF(is_cat, IF(header_row_id=income_header_row, MATCH(income_min_row, $C:$C, 0), IF(header_row_id=expenses_header_row, MATCH(expenses_min_row, $C:$C, 0), IF(header_row_id=savings_header_row, MATCH(savings_min_row, $C:$C, 0), ""))), "")} | N19: {=IF(is_cat, IF(header_row_id=income_header_row, MATCH(income_max_row, $C:$C, 0), IF(header_row_id=expenses_header_row, MATCH(expenses_max_row, $C:$C, 0), IF(header_row_id=savings_header_row, MATCH(savings_max_row, $C:$C, 0), ""))), "")} | O19: =IF(is_cat, ADDRESS(sort_min_row, COLUMN(tracked)) & ":" & ADDRESS(sort_max_row, COLUMN(tracked)), "") | P19: =IF(is_cat, RANK(tracked, INDIRECT(tracked_range), 0), "") | Q19: =IF(is_cat, ADDRESS(sort_min_row, COLUMN(budget)) & ":" & ADDRESS(sort_max_row, COLUMN(budget)), "") | R19: =IF(is_cat, RANK(budget, INDIRECT(budget_range), 0), "") | S19: =IF(is_cat, _xlfn.NUMBERVALUE(tracked_rank & budget_rank), "") | T19: =IF(is_cat, ADDRESS(sort_min_row, COLUMN(comb_rank)) & ":" & ADDRESS(sort_max_row, COLUMN(comb_rank)), "") | U19: =IF(is_cat, RANK(comb_rank, INDIRECT(comb_rank_range), 1), "") | V19: =IF(is_cat, ADDRESS(sort_min_row, COLUMN(comb_rank_norm)) & ":" & ADDRESS(ROW(), COLUMN(comb_rank_norm)), "") | W19: =IF(is_cat, comb_rank_norm + COUNTIF(INDIRECT(comb_rank_norm_run_range), comb_rank_norm)-1, "") | X19: =IF(is_cat, header_row_id + comb_rank_unique, row_id) | Y19: =IF(is_empty, "", INDEX($J:$J, MATCH(row_id, $X:$X, 0))) | Z19: =IF(is_empty, "", IF(is_header, "Tracked", INDEX($K:$K, MATCH(row_id, $X:$X, 0)))) | AA19: =IF(is_empty, "", IF(is_header, "Budget", INDEX($L:$L, MATCH(row_id, $X:$X, 0)))) | AB19: =IF(is_empty, "", IF(is_header, "% Compl.", IFERROR(out_tracked / out_budget, "-"))) | AC19: =IF(is_empty, "", IF(is_header, "Remaining", IF(out_budget - out_tracked > 0, out_budget - out_tracked, 0))) | AD19: =IF(is_empty, "", IF(is_header, "Excess", IF(out_budget - out_tracked < 0, out_tracked - out_budget, 0))) | AI19: =Calculation!E38 | AJ19: =Calculation!F38
